Workbook
Name Buick: Lists!$C$2:$C$3
Name Chevy: Lists!$C$4:$C$10
Name Chrysler: Lists!$C$11:$C$12
Name Fiat: Lists!$C$13:$C$14
Name Ford: Lists!$C$15:$C$18
Name Honda: Lists!$C$19:$C$23
Name Hyundai: Lists!$C$24:$C$29
Name Jeep: Lists!$C$30:$C$30
Name Kia: Lists!$C$31:$C$36
Name Mazda: Lists!$C$37:$C$39
Name Mini: Lists!$C$40:$C$41
Name Nissan: Lists!$C$42:$C$43
Name Porsche: Lists!$C$44:$C$45
Name Subaru: Lists!$C$46:$C$48
Name Tesla: Lists!$C$49:$C$49
Name Toyota: Lists!$C$50:$C$64
Name VW: Lists!$C$65:$C$69
Name Volvo: Lists!$C$70:$C$72
Name MAKES: Lists!$N$2:$N$19
Name YEARS: Lists!$O$2:$O$23
Name CARS: Lists!$A$2:$A$72

Sheet Start here
B2: TRUE COST OF OWNERSHIP — how this workbook is built, in four layers
B4: The goal: the true lifetime cost of owning each car, in cost-per-mile, driven to end-of-life. Everything is discounted at 7% real — the S&P 500 long-run return — so the money you sink into a car is charged its market opportunity cost. Costs come from a Monte-Carlo simulation (N=1,100 runs per car), so every number carries a measured uncertainty and the rankings come with a statistical-significance test.
B8: LAYER 1 — SURVEY
B9: → tab(s): Sweet-spot heat map
B10: A wide survey of EVERY model×year×odometer combination inside a broad filter. For each vehicle it maps $/mile across the whole odometer range and finds the cost-optimal buy point. This is the raw field the rankings are drawn from.
B13: LAYER 2 — RANKINGS
B14: → tab(s): Ranking (hardened)
B15: The best buy of each model pulled from the survey, ranked by median $/mile. Now with STATISTICAL TIE TIERS (cars you cannot tell apart), a 90% outcome band, the probability each car beats the next, and the market opportunity cost of the cash tied up.
B18: LAYER 3 — DEAL ANALYZER
B19: → tab(s): Any-Car Calculator
B20: Found a real listing? Type in its year, odometer and asking price (or pick from the dropdown) and it drops that exact car onto the ranked table — so you can see whether a specific deal beats the idealised picks above.
B23: LAYER 4 — ANALYSIS SUITE
... B33: Your basis: 13,000 mi/yr · USAA active-duty insurance · Florida registration · Fresno CA garaging · gas $5.455 / elec $0.32. Edit the yellow cells anywhere to re-run for different assumptions.

Sheet Sweet-spot heat map
A1: SWEET-SPOT HEAT MAP — median $/mile vs PURCHASE ODOMETER (California prices). Each column shows both the odometer AND the ≈ model year it implies at 13k mi/yr. Green = cheaper. Grey ▒ = infeasible (too few miles left before end-of-life, or that odometer would imply a year before the model existed). ★ = each vehicle's cheapest column; ◆ = pinned buy. LIVE: every cell is a formula tied to that car's editable Purchase $ on the Ranking tab — fix a price there and this whole row re-scales and re-colors. Every $/mile cell also links to a cars.com search at that odometer/price band so you can verify the price behind it.
A3: Vehicle | B3: 10k mi | C3: 20k mi | D3: 40k mi | E3: 60k mi | F3: 80k mi | G3: 100k mi | H3: 120k mi | I3: 150k mi | J3: 180k mi | K3: Lowest $/mi (newest) | L3: Buy pick ◆ (least cash) | M3: Pinned $/mi (live) | N3: Stat. tier | O3: 90% band $/mi (at pinned buy) | P3: Capital opp cost $/mi newest → oldest
A4: (cells link to cars.com; values live off Ranking price) | B4: ≈ 2025 | C4: ≈ 2024 | D4: ≈ 2023 | E4: ≈ 2021 | F4: ≈ 2020 | G4: ≈ 2018 | H4: ≈ 2017 | I4: ≈ 2014 | J4: ≈ 2012 | K4: ↓ cheapest per-mile | L4: ◆ least $ up-front · = Ranking | M4: (updates w/ your price) | N4: (tie group) | O4: (P5–P95 outcome) | P4: (scales w/ price: high when new)
A5: Chevy Bolt EV | B5: ▒ | C5: ▒ | D5: =0.22026+0.099429*'Ranking (hardened)'!$F$6/15643 | E5: =0.23874+0.105462*'Ranking (hardened)'!$F$6/15643 | F5: =0.24938+0.116473*'Ranking (hardened)'!$F$6/15643 | G5: =0.26201+0.133067*'Ranking (hardened)'!$F$6/15643 | H5: =0.27194+0.157107*'Ranking (hardened)'!$F$6/15643 | I5: ▒ | J5: ▒ | K5: ↓ 40k · ≈2023 | L5: ◆ 45k · ≈2023 · $15,643 | M5: =0.22331+0.100792*'Ranking (hardened)'!$F$6/15643 | N5: 1 | O5: $0.289–$0.389 | P5: $0.129 → $0.081
A6: Chevy Volt | B6: ▒ | C6: ▒ | D6: ▒ | E6: ▒ | F6: ▒ | G6: =0.26688+0.12475*'Ranking (hardened)'!$F$7/15143 | H6: =0.27719+0.143392*'Ranking (hardened)'!$F$7/15143 | I6: ▒ | J6: ▒ | K6: ↓ 100k · ≈2018 | L6: ◆ 55k · ≈2019 · $15,143 | M6: =0.23564+0.10429*'Ranking (hardened)'!$F$7/15143 | N6: 1 | O6: $0.307–$0.385 | P6: $0.085 → $0.074
A7: Toyota Prius (hybrid) | B7: =0.21025+0.116861*'Ranking (hardened)'!$F$8/26000 | C7: =0.21645+0.120209*'Ranking (hardened)'!$F$8/26000 | D7: =0.22881+0.124046*'Ranking (hardened)'!$F$8/26000 | E7: =0.24294+0.130098*'Ranking (hardened)'!$F$8/26000 | F7: =0.2564+0.133648*'Ranking (hardened)'!$F$8/26000 | G7: =0.26655+0.13369*'Ranking (hardened)'!$F$8/26000 | H7: =0.28486+0.133745*'Ranking (hardened)'!$F$8/26000 | I7: =0.29692+0.145582*'Ranking (hardened)'!$F$8/26000 | J7: =0.31285+0.175287*'Ranking (hardened)'!$F$8/26000 | K7: ↓ 10k · ≈2025 | L7: ◆ 40k · ≈2023 · $26,000 | M7: =0.22881+0.124046*'Ranking (hardened)'!$F$8/26000 | N7: 1 | O7: $0.321–$0.387 | P7: $0.290 → $0.077
A8: Toyota Prius Prime | B8: =0.2178+0.133156*'Ranking (hardened)'!$F$9/15000 | C8: =0.22364+0.130051*'Ranking (hardened)'!$F$9/15000 | D8: =0.2348+0.114354*'Ranking (hardened)'!$F$9/15000 | E8: =0.24502+0.108386*'Ranking (hardened)'!$F$9/15000 | F8: =0.2577+0.105173*'Ranking (hardened)'!$F$9/15000 | G8: =0.27185+0.105937*'Ranking (hardened)'!$F$9/15000 | H8: =0.30505+0.112749*'Ranking (hardened)'!$F$9/15000 | I8: ▒ | J8: ▒ | K8: ↓ 40k · ≈2023 | L8: ◆ 90k · ≈2019 · $15,000 | M8: =0.26449+0.103235*'Ranking (hardened)'!$F$9/15000 | N8: 2 | O8: $0.330–$0.415 | P8: $0.297 → $0.093
A9: Toyota Corolla | B9: =0.25+0.100167*'Ranking (hardened)'!$F$10/17659 | C9: =0.25644+0.093809*'Ranking (hardened)'!$F$10/17659 | D9: =0.27818+0.089695*'Ranking (hardened)'!$F$10/17659 | E9: =0.28315+0.091341*'Ranking (hardened)'!$F$10/17659 | F9: =0.31268+0.095603*'Ranking (hardened)'!$F$10/17659 | G9: =0.31611+0.10361*'Ranking (hardened)'!$F$10/17659 | H9: =0.33306+0.106739*'Ranking (hardened)'!$F$10/17659 | I9: =0.37744+0.115462*'Ranking (hardened)'!$F$10/17659 | J9: =0.38134+0.133621*'Ranking (hardened)'!$F$10/17659 | K9: ↓ 10k · ≈2025 | L9: ◆ 55k · ≈2022 · $17,659 | M9: =0.27875+0.090746*'Ranking (hardened)'!$F$10/17659 | N9: 2 | O9: $0.339–$0.402 | P9: $0.248 → $0.058
A10: Toyota Camry Hybrid | B10: =0.22903+0.129382*'Ranking (hardened)'!$F$11/16500 | C10: =0.23529+0.126307*'Ranking (hardened)'!$F$11/16500 | D10: =0.24704+0.105643*'Ranking (hardened)'!$F$11/16500 | E10: =0.25816+0.098704*'Ranking (hardened)'!$F$11/16500 | F10: =0.27228+0.097288*'Ranking (hardened)'!$F$11/16500 | G10: =0.30566+0.10361*'Ranking (hardened)'!$F$11/16500 | H10: =0.30892+0.110597*'Ranking (hardened)'!$F$11/16500 | I10: =0.32463+0.122992*'Ranking (hardened)'!$F$11/16500 | J10: =0.34563+0.143678*'Ranking (hardened)'!$F$11/16500 | K10: ↓ 40k · ≈2023 | L10: ◆ 80k · ≈2020 · $16,500 | M10: =0.27228+0.097288*'Ranking (hardened)'!$F$11/16500 | N10: 2 | O10: $0.335–$0.411 | P10: $0.321 → $0.063
A11: Honda Civic | B11: =0.24981+0.110963*'Ranking (hardened)'!$F$12/23789 | C11: =0.25693+0.114161*'Ranking (hardened)'!$F$12/23789 | D11: =0.27136+0.120462*'Ranking (hardened)'!$F$12/23789 | E11: =0.28444+0.127638*'Ranking (hardened)'!$F$12/23789 | F11: =0.29935+0.130393*'Ranking (hardened)'!$F$12/23789 | G11: =0.31548+0.133038*'Ranking (hardened)'!$F$12/23789 | H11: =0.3356+0.138768*'Ranking (hardened)'!$F$12/23789 | I11: =0.35046+0.152403*'Ranking (hardened)'!$F$12/23789 | J11: =0.36578+0.180832*'Ranking (hardened)'!$F$12/23789 | K11: ↓ 10k · ≈2025 | L11: ◆ 35k · ≈2023 · $23,789 | M11: =0.26782+0.118769*'Ranking (hardened)'!$F$12/23789 | N11: 2 | O11: $0.357–$0.417 | P11: $0.247 → $0.060
A12: Nissan Leaf | B12: =0.24918+0.145706*'Ranking (hardened)'!$F$13/11667 | C12: =0.25528+0.137585*'Ranking (hardened)'!$F$13/11667 | D12: =0.2651+0.117862*'Ranking (hardened)'!$F$13/11667 | E12: =0.27948+0.138889*'Ranking (hardened)'!$F$13/11667 | F12: =0.29131+0.167928*'Ranking (hardened)'!$F$13/11667 | G12: =0.32324+0.222772*'Ranking (hardened)'!$F$13/11667 | H12: ▒ | I12: ▒ | J12: ▒ | K12: ↓ 40k · ≈2023 | L12: ◆ 45k · ≈2023 · $11,667 | M12: =0.27075+0.122292*'Ranking (hardened)'!$F$13/11667 | N12: 2 | O12: $0.339–$0.473 | P12: $0.142 → $0.052
A13: Hyundai Elantra | B13: =0.25719+0.105152*'Ranking (hardened)'!$F$14/16000 | C13: =0.26681+0.105197*'Ranking (hardened)'!$F$14/16000 | D13: =0.28207+0.102996*'Ranking (hardened)'!$F$14/16000 | E13: =0.29856+0.103424*'Ranking (hardened)'!$F$14/16000 | F13: =0.31405+0.103993*'Ranking (hardened)'!$F$14/16000 | G13: =0.33223+0.105503*'Ranking (hardened)'!$F$14/16000 | H13: =0.38062+0.110438*'Ranking (hardened)'!$F$14/16000 | I13: =0.37007+0.130905*'Ranking (hardened)'!$F$14/16000 | J13: =0.35405+0.272277*'Ranking (hardened)'!$F$14/16000 | K13: ↓ 10k · ≈2025 | L13: ◆ 45k · ≈2023 · $16,000 | M13: =0.28879+0.103093*'Ranking (hardened)'!$F$14/16000 | N13: 2 | O13: $0.357–$0.432 | P13: $0.178 → $0.030
A14: Honda Accord | B14: =0.25436+0.121475*'Ranking (hardened)'!$F$15/16143 | C14: =0.26071+0.115322*'Ranking (hardened)'!$F$15/16143 | D14: =0.27439+0.094763*'Ranking (hardened)'!$F$15/16143 | E14: =0.28624+0.094183*'Ranking (hardened)'!$F$15/16143 | F14: =0.30262+0.096128*'Ranking (hardened)'!$F$15/16143 | G14: =0.33599+0.099644*'Ranking (hardened)'!$F$15/16143 | H14: =0.33226+0.107884*'Ranking (hardened)'!$F$15/16143 | I14: =0.35849+0.124309*'Ranking (hardened)'!$F$15/16143 | J14: =0.36236+0.14876*'Ranking (hardened)'!$F$15/16143 | K14: ↓ 40k · ≈2023 | L14: ◆ 70k · ≈2021 · $16,143 | M14: =0.29392+0.09468*'Ranking (hardened)'!$F$15/16143 | N14: 2 | O14: $0.355–$0.425 | P14: $0.282 → $0.055
A15: Kia K4 | B15: =0.27346+0.114016*'Ranking (hardened)'!$F$16/20125 | C15: ▒ | D15: ▒ | E15: ▒ | F15: ▒ | G15: ▒ | H15: ▒ | I15: ▒ | J15: ▒ | K15: ↓ 10k · ≈2025 | L15: ◆ 18k · ≈2025 · $20,125 | M15: =0.28088+0.117142*'Ranking (hardened)'!$F$16/20125 | N15: 2 | O15: $0.369–$0.436 | P15: $0.177 → $0.177
A16: Mazda3 (SkyActiv) | B16: =0.259+0.119641*'Ranking (hardened)'!$F$17/15000 | C16: =0.26691+0.114675*'Ranking (hardened)'!$F$17/15000 | D16: =0.27892+0.096717*'Ranking (hardened)'!$F$17/15000 | E16: =0.29015+0.101594*'Ranking (hardened)'!$F$17/15000 | F16: =0.30896+0.101072*'Ranking (hardened)'!$F$17/15000 | G16: =0.31679+0.097197*'Ranking (hardened)'!$F$17/15000 | H16: =0.33057+0.096578*'Ranking (hardened)'!$F$17/15000 | I16: =0.36053+0.115512*'Ranking (hardened)'!$F$17/15000 | J16: =0.29861+0.179739*'Ranking (hardened)'!$F$17/15000 | K16: ↓ 40k · ≈2023 | L16: ◆ 65k · ≈2021 · $15,000 | M16: =0.2945+0.103022*'Ranking (hardened)'!$F$17/15000 | N16: 2 | O16: $0.364–$0.441 | P16: $0.220 → $0.031
A17: Toyota Camry | B17: =0.2552+0.114379*'Ranking (hardened)'!$F$18/22400 | C17: =0.26255+0.114767*'Ranking (hardened)'!$F$18/22400 | D17: =0.27754+0.113202*'Ranking (hardened)'!$F$18/22400 | E17: =0.29121+0.11191*'Ranking (hardened)'!$F$18/22400 | F17: =0.30781+0.110984*'Ranking (hardened)'!$F$18/22400 | G17: =0.34363+0.109819*'Ranking (hardened)'!$F$18/22400 | H17: =0.34534+0.111276*'Ranking (hardened)'!$F$18/22400 | I17: =0.37945+0.119275*'Ranking (hardened)'!$F$18/22400 | J17: =0.40875+0.13369*'Ranking (hardened)'!$F$18/22400 | K17: ↓ 10k · ≈2025 | L17: ◆ 55k · ≈2022 · $22,400 | M17: =0.28655+0.112112*'Ranking (hardened)'!$F$18/22400 | N17: 2 | O17: $0.363–$0.436 | P17: $0.295 → $0.064
A18: Toyota RAV4 Hybrid | B18: =0.23144+0.145051*'Ranking (hardened)'!$F$19/30444 | C18: =0.23767+0.147059*'Ranking (hardened)'!$F$19/30444 | D18: =0.25008+0.148945*'Ranking (hardened)'!$F$19/30444 | E18: =0.2614+0.159074*'Ranking (hardened)'!$F$19/30444 | F18: =0.27797+0.162206*'Ranking (hardened)'!$F$19/30444 | G18: =0.28833+0.166205*'Ranking (hardened)'!$F$19/30444 | H18: =0.30144+0.17283*'Ranking (hardened)'!$F$19/30444 | I18: ▒ | J18: ▒ | K18: ↓ 10k · ≈2025 | L18: ◆ 40k · ≈2023 · $30,444 | M18: =0.25008+0.148945*'Ranking (hardened)'!$F$19/30444 | N18: 2 | O18: $0.359–$0.437 | P18: $0.346 → $0.157
A19: Kia Niro (hybrid) | B19: =0.24178+0.13306*'Ranking (hardened)'!$F$20/17000 | C19: =0.25024+0.134844*'Ranking (hardened)'!$F$20/17000 | D19: =0.2661+0.126965*'Ranking (hardened)'!$F$20/17000 | E19: =0.28137+0.122421*'Ranking (hardened)'!$F$20/17000 | F19: =0.29945+0.123604*'Ranking (hardened)'!$F$20/17000 | G19: =0.32224+0.126502*'Ranking (hardened)'!$F$20/17000 | H19: =0.37213+0.124902*'Ranking (hardened)'!$F$20/17000 | I19: ▒ | J19: ▒ | K19: ↓ 10k · ≈2025 | L19: ◆ 65k · ≈2021 · $17,000 | M19: =0.28517+0.121083*'Ranking (hardened)'!$F$20/17000 | N19: 3 | O19: $0.367–$0.460 | P19: $0.235 → $0.070
A20: Tesla Model 3 | B20: =0.2568+0.154475*'Ranking (hardened)'!$F$21/21500 | C20: =0.26453+0.153668*'Ranking (hardened)'!$F$21/21500 | D20: =0.27518+0.133764*'Ranking (hardened)'!$F$21/21500 | E20: =0.29316+0.126396*'Ranking (hardened)'!$F$21/21500 | F20: =0.31136+0.133245*'Ranking (hardened)'!$F$21/21500 | G20: =0.35548+0.138355*'Ranking (hardened)'!$F$21/21500 | H20: ▒ | I20: ▒ | J20: ▒ | K20: ↓ 40k · ≈2023 | L20: ◆ 60k · ≈2021 · $21,500 | M20: =0.29316+0.126396*'Ranking (hardened)'!$F$21/21500 | N20: 3 | O20: $0.367–$0.503 | P20: $0.331 → $0.134
A21: Hyundai Sonata | B21: =0.2727+0.118919*'Ranking (hardened)'!$F$22/15333 | C21: =0.28104+0.121143*'Ranking (hardened)'!$F$22/15333 | D21: =0.29615+0.116129*'Ranking (hardened)'!$F$22/15333 | E21: =0.31268+0.11358*'Ranking (hardened)'!$F$22/15333 | F21: =0.32753+0.113043*'Ranking (hardened)'!$F$22/15333 | G21: =0.34994+0.115789*'Ranking (hardened)'!$F$22/15333 | H21: =0.37026+0.12381*'Ranking (hardened)'!$F$22/15333 | I21: =0.43761+0.153968*'Ranking (hardened)'!$F$22/15333 | J21: ▒ | K21: ↓ 10k · ≈2025 | L21: ◆ 60k · ≈2021 · $15,333 | M21: =0.31268+0.11358*'Ranking (hardened)'!$F$22/15333 | N21: 3 | O21: $0.387–$0.478 | P21: $0.193 → $0.041
A22: Toyota RAV4 | B22: =0.25799+0.143167*'Ranking (hardened)'!$F$23/20600 | C22: =0.26438+0.14059*'Ranking (hardened)'!$F$23/20600 | D22: =0.27779+0.142643*'Ranking (hardened)'!$F$23/20600 | E22: =0.28915+0.134349*'Ranking (hardened)'!$F$23/20600 | F22: =0.3058+0.128349*'Ranking (hardened)'!$F$23/20600 | G22: =0.31761+0.128114*'Ranking (hardened)'!$F$23/20600 | H22: =0.33231+0.13278*'Ranking (hardened)'!$F$23/20600 | I22: =0.3954+0.160835*'Ranking (hardened)'!$F$23/20600 | J22: ▒ | K22: ↓ 10k · ≈2025 | L22: ◆ 80k · ≈2020 · $20,600 | M22: =0.3058+0.128349*'Ranking (hardened)'!$F$23/20600 | N22: 3 | O22: $0.396–$0.477 | P22: $0.332 → $0.097
A23: Fiat 500 | B23: ▒ | C23: ▒ | D23: ▒ | E23: ▒ | F23: ▒ | G23: =0.45103+0.094602*'Ranking (hardened)'!$F$24/10200 | H23: =0.4914+0.112782*'Ranking (hardened)'!$F$24/10200 | I23: ▒ | J23: ▒ | K23: ↓ 100k · ≈2018 | L23: ◆ 40k · ≈2019 · $10,200 | M23: =0.35714+0.085071*'Ranking (hardened)'!$F$24/10200 | N23: 3 | O23: $0.409–$0.496 | P23: $0.035 → $0.026
A24: Honda CR-V | B24: =0.26686+0.13449*'Ranking (hardened)'!$F$25/20500 | C24: =0.27439+0.135407*'Ranking (hardened)'!$F$25/20500 | D24: =0.28897+0.126113*'Ranking (hardened)'!$F$25/20500 | E24: =0.30214+0.121884*'Ranking (hardened)'!$F$25/20500 | F24: =0.31835+0.124611*'Ranking (hardened)'!$F$25/20500 | G24: =0.37734+0.128114*'Ranking (hardened)'!$F$25/20500 | H24: =0.40007+0.13278*'Ranking (hardened)'!$F$25/20500 | I24: =0.38336+0.145225*'Ranking (hardened)'!$F$25/20500 | J24: =0.40085+0.173554*'Ranking (hardened)'!$F$25/20500 | K24: ↓ 10k · ≈2025 | L24: ◆ 75k · ≈2020 · $20,500 | M24: =0.31464+0.123867*'Ranking (hardened)'!$F$25/20500 | N24: 3 | O24: $0.400–$0.480 | P24: $0.312 → $0.064
A25: VW ID.4 (AWD avail) | B25: =0.26709+0.162162*'Ranking (hardened)'!$F$26/22500 | C25: =0.27233+0.16*'Ranking (hardened)'!$F$26/22500 | D25: =0.28599+0.148387*'Ranking (hardened)'!$F$26/22500 | E25: =0.32399+0.155556*'Ranking (hardened)'!$F$26/22500 | F25: ▒ | G25: ▒ | H25: ▒ | I25: ▒ | J25: ▒ | K25: ↓ 10k · ≈2025 | L25: ◆ 45k · ≈2023 · $22,500 | M25: =0.29271+0.15*'Ranking (hardened)'!$F$26/22500 | N25: 3 | O25: $0.389–$0.529 | P25: $0.263 → $0.159
A26: Toyota RAV4 Prime | B26: =0.22684+0.186418*'Ranking (hardened)'!$F$27/35000 | C26: =0.23238+0.190432*'Ranking (hardened)'!$F$27/35000 | D26: =0.23982+0.189452*'Ranking (hardened)'!$F$27/35000 | E26: =0.26381+0.195855*'Ranking (hardened)'!$F$27/35000 | F26: ▒ | G26: ▒ | H26: ▒ | I26: ▒ | J26: ▒ | K26: ↓ 10k · ≈2025 | L26: ◆ 55k · ≈2022 · $35,000 | M26: =0.24778+0.194121*'Ranking (hardened)'!$F$27/35000 | N26: 3 | O26: $0.402–$0.484 | P26: $0.416 → $0.292
A27: Kia Soul | B27: =0.2868+0.126002*'Ranking (hardened)'!$F$28/14500 | C27: =0.29493+0.123092*'Ranking (hardened)'!$F$28/14500 | D27: =0.31221+0.114108*'Ranking (hardened)'!$F$28/14500 | E27: =0.32682+0.116372*'Ranking (hardened)'!$F$28/14500 | F27: =0.36584+0.119503*'Ranking (hardened)'!$F$28/14500 | G27: =0.36289+0.124113*'Ranking (hardened)'!$F$28/14500 | H27: =0.38085+0.131579*'Ranking (hardened)'!$F$28/14500 | I27: =0.42533+0.179604*'Ranking (hardened)'!$F$28/14500 | J27: ▒ | K27: ↓ 10k · ≈2025 | L27: ◆ 60k · ≈2021 · $14,500 | M27: =0.32682+0.116372*'Ranking (hardened)'!$F$28/14500 | N27: 3 | O27: $0.406–$0.494 | P27: $0.187 → $0.035
A28: VW Passat | B28: ▒ | C28: ▒ | D28: ▒ | E28: =0.35502+0.104777*'Ranking (hardened)'!$F$29/14200 | F28: =0.37334+0.104736*'Ranking (hardened)'!$F$29/14200 | G28: =0.39384+0.107381*'Ranking (hardened)'!$F$29/14200 | H28: =0.40994+0.117683*'Ranking (hardened)'!$F$29/14200 | I28: =0.41646+0.152548*'Ranking (hardened)'!$F$29/14200 | J28: ▒ | K28: ↓ 60k · ≈2021 | L28: ◆ 55k · ≈2022 · $14,200 | M28: =0.34606+0.105341*'Ranking (hardened)'!$F$29/14200 | N28: 4 | O28: $0.412–$0.507 | P28: $0.101 → $0.035
A29: Buick Encore | B29: =0.29909+0.120846*'Ranking (hardened)'!$F$30/14800 | C29: =0.30803+0.123473*'Ranking (hardened)'!$F$30/14800 | D29: =0.32656+0.118081*'Ranking (hardened)'!$F$30/14800 | E29: =0.34619+0.117749*'Ranking (hardened)'!$F$30/14800 | F29: =0.36053+0.120419*'Ranking (hardened)'!$F$30/14800 | G29: =0.37754+0.126932*'Ranking (hardened)'!$F$30/14800 | H29: =0.39436+0.142643*'Ranking (hardened)'!$F$30/14800 | I29: =0.38774+0.212418*'Ranking (hardened)'!$F$30/14800 | J29: ▒ | K29: ↓ 10k · ≈2025 | L29: ◆ 50k · ≈2022 · $14,800 | M29: =0.33631+0.117928*'Ranking (hardened)'!$F$30/14800 | N29: 4 | O29: $0.419–$0.499 | P29: $0.165 → $0.030
A30: Hyundai Kona | B30: =0.28665+0.137457*'Ranking (hardened)'!$F$31/15000 | C30: =0.29584+0.139733*'Ranking (hardened)'!$F$31/15000 | D30: =0.31274+0.131397*'Ranking (hardened)'!$F$31/15000 | E30: =0.32914+0.126806*'Ranking (hardened)'!$F$31/15000 | F30: =0.34724+0.129063*'Ranking (hardened)'!$F$31/15000 | G30: =0.39379+0.135934*'Ranking (hardened)'!$F$31/15000 | H30: ▒ | I30: ▒ | J30: ▒ | K30: ↓ 10k · ≈2025 | L30: ◆ 65k · ≈2021 · $15,000 | M30: =0.33293+0.125418*'Ranking (hardened)'!$F$31/15000 | N30: 4 | O30: $0.423–$0.504 | P30: $0.204 → $0.075
A31: Mazda CX-5 | B31: =0.28425+0.141809*'Ranking (hardened)'!$F$32/20600 | C31: =0.29216+0.143959*'Ranking (hardened)'!$F$32/20600 | D31: =0.3074+0.137536*'Ranking (hardened)'!$F$32/20600 | E31: =0.32085+0.137217*'Ranking (hardened)'!$F$32/20600 | F31: =0.33642+0.137546*'Ranking (hardened)'!$F$32/20600 | G31: =0.35779+0.136827*'Ranking (hardened)'!$F$32/20600 | H31: =0.36711+0.137566*'Ranking (hardened)'!$F$32/20600 | I31: =0.40607+0.166667*'Ranking (hardened)'!$F$32/20600 | J31: ▒ | K31: ↓ 10k · ≈2025 | L31: ◆ 65k · ≈2021 · $20,600 | M31: =0.32463+0.137793*'Ranking (hardened)'!$F$32/20600 | N31: 4 | O31: $0.427–$0.505 | P31: $0.269 → $0.066
A32: Toyota Highlander Hybrid | B32: =0.25617+0.183447*'Ranking (hardened)'!$F$33/32000 | C32: =0.2635+0.186275*'Ranking (hardened)'!$F$33/32000 | D32: =0.2777+0.181018*'Ranking (hardened)'!$F$33/32000 | E32: =0.29029+0.178959*'Ranking (hardened)'!$F$33/32000 | F32: =0.32199+0.176399*'Ranking (hardened)'!$F$33/32000 | G32: =0.32249+0.175439*'Ranking (hardened)'!$F$33/32000 | H32: =0.33938+0.176849*'Ranking (hardened)'!$F$33/32000 | I32: =0.36172+0.180085*'Ranking (hardened)'!$F$33/32000 | J32: =0.38535+0.205745*'Ranking (hardened)'!$F$33/32000 | K32: ↓ 10k · ≈2025 | L32: ◆ 65k · ≈2021 · $32,000 | M32: =0.29392+0.178372*'Ranking (hardened)'!$F$33/32000 | N32: 4 | O32: $0.425–$0.524 | P32: $0.438 → $0.082
A33: Subaru Outback | B33: =0.28367+0.159521*'Ranking (hardened)'!$F$34/18800 | C33: =0.29235+0.160021*'Ranking (hardened)'!$F$34/18800 | D33: =0.30799+0.143611*'Ranking (hardened)'!$F$34/18800 | E33: =0.32314+0.138778*'Ranking (hardened)'!$F$34/18800 | F33: =0.3405+0.139357*'Ranking (hardened)'!$F$34/18800 | G33: =0.36783+0.144665*'Ranking (hardened)'!$F$34/18800 | H33: =0.38743+0.152318*'Ranking (hardened)'!$F$34/18800 | I33: =0.46688+0.178218*'Ranking (hardened)'!$F$34/18800 | J33: =0.43223+0.281046*'Ranking (hardened)'!$F$34/18800 | K33: ↓ 10k · ≈2025 | L33: ◆ 75k · ≈2020 · $18,800 | M33: =0.337+0.138643*'Ranking (hardened)'!$F$34/18800 | N33: 4 | O33: $0.432–$0.538 | P33: $0.294 → $0.049
A34: Subaru Forester | B34: =0.28754+0.152471*'Ranking (hardened)'!$F$35/22200 | C34: =0.29644+0.155383*'Ranking (hardened)'!$F$35/22200 | D34: =0.31281+0.149813*'Ranking (hardened)'!$F$35/22200 | E34: =0.32847+0.154066*'Ranking (hardened)'!$F$35/22200 | F34: =0.34614+0.166389*'Ranking (hardened)'!$F$35/22200 | G34: =0.37379+0.182136*'Ranking (hardened)'!$F$35/22200 | H34: =0.39163+0.19015*'Ranking (hardened)'!$F$35/22200 | I34: =0.46595+0.229084*'Ranking (hardened)'!$F$35/22200 | J34: =0.33705+0.442794*'Ranking (hardened)'!$F$35/22200 | K34: ↓ 10k · ≈2025 | L34: ◆ 55k · ≈2022 · $22,200 | M34: =0.32222+0.152893*'Ranking (hardened)'!$F$35/22200 | N34: 4 | O34: $0.439–$0.523 | P34: $0.258 → $0.049
A35: Toyota Sienna Hybrid | B35: =0.25138+0.187713*'Ranking (hardened)'!$F$36/35000 | C35: =0.25891+0.190508*'Ranking (hardened)'!$F$36/35000 | D35: =0.27374+0.18591*'Ranking (hardened)'!$F$36/35000 | E35: =0.29085+0.184382*'Ranking (hardened)'!$F$36/35000 | F35: ▒ | G35: ▒ | H35: ▒ | I35: ▒ | J35: ▒ | K35: ↓ 10k · ≈2025 | L35: ◆ 55k · ≈2022 · $35,000 | M35: =0.28603+0.184794*'Ranking (hardened)'!$F$36/35000 | N35: 4 | O35: $0.416–$0.525 | P35: $0.448 → $0.297
A36: Toyota Tacoma | B36: =0.29764+0.146481*'Ranking (hardened)'!$F$37/29333 | C36: =0.30457+0.143263*'Ranking (hardened)'!$F$37/29333 | D36: =0.31869+0.136054*'Ranking (hardened)'!$F$37/29333 | E36: =0.33158+0.136291*'Ranking (hardened)'!$F$37/29333 | F36: =0.34705+0.136573*'Ranking (hardened)'!$F$37/29333 | G36: =0.36387+0.136914*'Ranking (hardened)'!$F$37/29333 | H36: =0.38532+0.137336*'Ranking (hardened)'!$F$37/29333 | I36: =0.40434+0.138194*'Ranking (hardened)'!$F$37/29333 | J36: =0.42587+0.145587*'Ranking (hardened)'!$F$37/29333 | K36: ↓ 10k · ≈2025 | L36: ◆ 75k · ≈2020 · $29,333 | M36: =0.34342+0.136498*'Ranking (hardened)'!$F$37/29333 | N36: 4 | O36: $0.440–$0.531 | P36: $0.482 → $0.112
A37: Nissan Rogue | B37: =0.29397+0.168434*'Ranking (hardened)'!$F$38/18800 | C37: =0.30318+0.170326*'Ranking (hardened)'!$F$38/18800 | D37: =0.3182+0.153492*'Ranking (hardened)'!$F$38/18800 | E37: =0.33568+0.166818*'Ranking (hardened)'!$F$38/18800 | F37: =0.37189+0.172757*'Ranking (hardened)'!$F$38/18800 | G37: =0.42966+0.177809*'Ranking (hardened)'!$F$38/18800 | H37: =0.45221+0.202783*'Ranking (hardened)'!$F$38/18800 | I37: =0.36726+0.369458*'Ranking (hardened)'!$F$38/18800 | J37: ▒ | K37: ↓ 10k · ≈2025 | L37: ◆ 55k · ≈2022 · $18,800 | M37: =0.32801+0.163053*'Ranking (hardened)'!$F$38/18800 | N37: 4 | O37: $0.451–$0.541 | P37: $0.219 → $0.041
A38: Chevy Equinox | B38: =0.31135+0.151057*'Ranking (hardened)'!$F$39/17200 | C38: =0.32162+0.153055*'Ranking (hardened)'!$F$39/17200 | D38: =0.33912+0.140221*'Ranking (hardened)'!$F$39/17200 | E38: =0.35802+0.143723*'Ranking (hardened)'!$F$39/17200 | F38: =0.40063+0.158564*'Ranking (hardened)'!$F$39/17200 | G38: =0.43188+0.18543*'Ranking (hardened)'!$F$39/17200 | H38: =0.41867+0.198198*'Ranking (hardened)'!$F$39/17200 | I38: =0.37242+0.303922*'Ranking (hardened)'!$F$39/17200 | J38: ▒ | K38: ↓ 10k · ≈2025 | L38: ◆ 55k · ≈2022 · $17,200 | M38: =0.34983+0.142739*'Ranking (hardened)'!$F$39/17200 | N38: 5 | O38: $0.455–$0.546 | P38: $0.206 → $0.043
A39: Toyota Sienna (V6) | B39: ▒ | C39: ▒ | D39: ▒ | E39: ▒ | F39: =0.38606+0.123682*'Ranking (hardened)'!$F$40/22333 | G39: =0.40839+0.122345*'Ranking (hardened)'!$F$40/22333 | H39: =0.44641+0.120579*'Ranking (hardened)'!$F$40/22333 | I39: =0.46542+0.127119*'Ranking (hardened)'!$F$40/22333 | J39: =0.49857+0.139752*'Ranking (hardened)'!$F$40/22333 | K39: ↓ 80k · ≈2020 | L39: ◆ 65k · ≈2020 · $22,333 | M39: =0.37071+0.124489*'Ranking (hardened)'!$F$40/22333 | N39: 5 | O39: $0.457–$0.533 | P39: $0.167 → $0.056
A40: Mini Cooper | B40: =0.31558+0.145015*'Ranking (hardened)'!$F$41/18200 | C40: =0.32715+0.14791*'Ranking (hardened)'!$F$41/18200 | D40: =0.34956+0.140221*'Ranking (hardened)'!$F$41/18200 | E40: =0.37643+0.136797*'Ranking (hardened)'!$F$41/18200 | F40: =0.40169+0.136126*'Ranking (hardened)'!$F$41/18200 | G40: =0.4223+0.139073*'Ranking (hardened)'!$F$41/18200 | H40: =0.45057+0.153153*'Ranking (hardened)'!$F$41/18200 | I40: =0.44344+0.243697*'Ranking (hardened)'!$F$41/18200 | J40: ▒ | K40: ↓ 10k · ≈2025 | L40: ◆ 45k · ≈2023 · $18,200 | M40: =0.35712+0.139464*'Ranking (hardened)'!$F$41/18200 | N40: 5 | O40: $0.451–$0.566 | P40: $0.198 → $0.035
A41: Ford Ranger (old compact) | B41: ▒ | C41: ▒ | D41: ▒ | E41: ▒ | F41: ▒ | G41: ▒ | H41: ▒ | I41: ▒ | J41: ▒ | K41: — | L41: ◆ 55k · ≈2011 · $11,500 | M41: =0.42824+0.0721*'Ranking (hardened)'!$F$42/11500 | N41: 5 | O41: $0.467–$0.547 | P41: —
...

Sheet Ranking (hardened)
A1: LAYER 2 — RANKINGS. Drive-to-death cost per mile (P50 median), discounted at the market opportunity-cost rate (default 7% real S&P; ADJUSTABLE in the yellow "Opp-cost rate" cell — the last two columns re-price and re-rank live at your rate). Right-side columns show the STATISTICAL TIE TIER (cars in the same tier are not distinguishable), the 90% outcome band, the probability this car beats the next-ranked one, and the lifetime market growth you forgo by tying cash in the car. The far-right "v1 $/mi (old)" is the pre-audit model. Edit yellow gas/electricity + per-car Purchase $ to re-rank live.
B3: INPUTS → | C3: Gas $/gal | D3: 5.455 | E3: Electricity $/kWh | F3: 0.32 | H3: Presets: CA $5.455/$0.320 • US avg $3.86/$0.177 • cheap state $3.00/$0.120 • home-EV ~$0.11. N=1,100 Monte-Carlo draws; discount 7% real (S&P opportunity cost); EOL "maintained" (iSeeCars ×1.30). INSURANCE = USAA active-duty (~×0.8 of standard) + FLORIDA registration (home of record), not CA — see Method tab. | Q3: 0.07 | R3: (3–12% real; 7%=S&P long-run. Cols W,X = "$/mi @ your rate" + "Rank @ your rate", live. A HIGHER rate lowers every $/mi in present-value terms but re-ranks TOWARD cheaper-to-buy cars — watch the Rank column, not the absolute number.)
A5: Rank | B5: Vehicle | C5: Body | D5: Energy | E5: Buy odo → ~yr | F5: Purchase $ (EDIT ↓) | G5: TOTAL $/mi (P50) | H5: $/mi P75 | I5: $/mi P90 (bad luck) | J5: $/mi if EOL=empirical | K5: Energy $/mi | L5: Non-energy $/mi | M5: Insur. $/yr | N5: Verify — live listing (click) | O5: openpilot supported YEARS (comma.ai) | P5: v1 $/mi (old model) | Q5: Stat. tier | R5: 90% band low | S5: 90% band high | T5: Beats next rank (P) | U5: Capital opp cost $/mi | V5: Foregone mkt growth (life $) | W5: $/mi @ your rate | X5: Rank @ your rate
A6: 1 | B6: Chevy Bolt EV | C6: EV | D6: electric | E6: 45k mi → ~2023 | F6: 15643 | G6: =0.2429+(F6-15643)/155200+0.0*$D$3+0.22608*$F$3 | H6: =0.2701+(F6-15643)/155200+0.0*$D$3+0.22608*$F$3 | I6: =0.2992+(F6-15643)/155200+0.0*$D$3+0.22608*$F$3 | J6: =0.2626+(F6-15643)/109000+0.0*$D$3+0.22608*$F$3 | K6: =0.0*$D$3+0.22608*$F$3 | L6: =G6-K6 | M6: 1660 | N6: live listings ~45k mi, $13,000-$17,500 | O6: ✓ supported 2022–23 (buy ~2023 ✓) | P6: 0.338 | Q6: 1 | R6: 0.289 | S6: 0.389 | T6: 0.688 | U6: 0.125 | V6: 19441 | W6: =IFERROR(G6*INDEX('Charts data (helper)'!$BI$119:$DZ$128,MATCH($Q$3,'Charts data (helper)'!$BH$119:$BH$128,0),MATCH($B6,'Charts data (helper)'!$BI$118:$DZ$118,0))/INDEX('Charts data (helper)'!$BI$119:$DZ$128,MATCH(0.07,'Charts data (helper)'!$BH$119:$BH$128,0),MATCH($B6,'Charts data (helper)'!$BI$118:$DZ$118,0)),G6) | X6: =RANK(W6,$W$6:$W$76,1)
A7: 2 | B7: Chevy Volt | C7: PHEV | D7: plug-in | E7: 55k mi → ~2019 | F7: 15143 | G7: =0.2552+(F7-15143)/145200+0.00334*$D$3+0.19367*$F$3 | H7: =0.2731+(F7-15143)/145200+0.00334*$D$3+0.19367*$F$3 | I7: =0.2902+(F7-15143)/145200+0.00334*$D$3+0.19367*$F$3 | J7: =0.2787+(F7-15143)/99000+0.00334*$D$3+0.19367*$F$3 | K7: =0.00334*$D$3+0.19367*$F$3 | L7: =G7-K7 | M7: 1440 | N7: live listings ~55k mi, $12,500-$17,000 | O7: ✗ not on current list | P7: 0.35 | Q7: 1 | R7: 0.307 | S7: 0.385 | T7: 0.697 | U7: 0.118 | V7: 17098 | W7: =IFERROR(G7*INDEX('Charts data (helper)'!$BI$119:$DZ$128,MATCH($Q$3,'Charts data (helper)'!$BH$119:$BH$128,0),MATCH($B7,'Charts data (helper)'!$BI$118:$DZ$118,0))/INDEX('Charts data (helper)'!$BI$119:$DZ$128,MATCH(0.07,'Charts data (helper)'!$BH$119:$BH$128,0),MATCH($B7,'Charts data (helper)'!$BI$118:$DZ$118,0)),G7) | X7: =RANK(W7,$W$6:$W$76,1)
A8: 3 | B8: Toyota Prius (hybrid) | C8: Car | D8: hybrid | E8: 40k mi → ~2023 | F8: 26000 | G8: =0.2866+(F8-26000)/209600+0.01217*$D$3+0.0*$F$3 | H8: =0.2995+(F8-26000)/209600+0.01217*$D$3+0.0*$F$3 | I8: =0.312+(F8-26000)/209600+0.01217*$D$3+0.0*$F$3 | J8: =0.3239+(F8-26000)/152000+0.01217*$D$3+0.0*$F$3 | K8: =0.01217*$D$3+0.0*$F$3 | L8: =G8-K8 | M8: 1800 | N8: live listings ~40k mi, $22,000-$29,500 | O8: ◑ supported 2016–22 (buy ~2023 OUTSIDE range — pick a 2016-2022 example instead) | P8: 0.348 | Q8: 1 | R8: 0.321 | S8: 0.387 | T8: 0.65 | U8: 0.245 | V8: 51398 | W8: =IFERROR(G8*INDEX('Charts data (helper)'!$BI$119:$DZ$128,MATCH($Q$3,'Charts data (helper)'!$BH$119:$BH$128,0),MATCH($B8,'Charts data (helper)'!$BI$118:$DZ$118,0))/INDEX('Charts data (helper)'!$BI$119:$DZ$128,MATCH(0.07,'Charts data (helper)'!$BH$119:$BH$128,0),MATCH($B8,'Charts data (helper)'!$BI$118:$DZ$118,0)),G8) | X8: =RANK(W8,$W$6:$W$76,1)
A9: 4 | B9: Toyota Prius Prime | C9: PHEV | D9: plug-in | E9: 90k mi → ~2019 | F9: 15000 | G9: =0.298+(F9-15000)/145300+0.00585*$D$3+0.10735*$F$3 | H9: =0.3161+(F9-15000)/145300+0.00585*$D$3+0.10735*$F$3 | I9: =0.3355+(F9-15000)/145300+0.00585*$D$3+0.10735*$F$3 | J9: =0.3358+(F9-15000)/91000+0.00585*$D$3+0.10735*$F$3 | K9: =0.00585*$D$3+0.10735*$F$3 | L9: =G9-K9 | M9: 1920 | N9: live listings ~90k mi, $12,500-$17,000 | O9: ✓ supported 2017–22 (buy ~2019 ✓) | P9: 0.37 | Q9: 2 | R9: 0.33 | S9: 0.415 | T9: 0.549 | U9: 0.117 | V9: 16953 | W9: =IFERROR(G9*INDEX('Charts data (helper)'!$BI$119:$DZ$128,MATCH($Q$3,'Charts data (helper)'!$BH$119:$BH$128,0),MATCH($B9,'Charts data (helper)'!$BI$118:$DZ$118,0))/INDEX('Charts data (helper)'!$BI$119:$DZ$128,MATCH(0.07,'Charts data (helper)'!$BH$119:$BH$128,0),MATCH($B9,'Charts data (helper)'!$BI$118:$DZ$118,0)),G9) | X9: =RANK(W9,$W$6:$W$76,1)
A10: 5 | B10: Toyota Corolla | C10: Car | D10: gas | E10: 55k mi → ~2022 | F10: 17659 | G10: =0.2577+(F10-17659)/194600+0.02028*$D$3+0.0*$F$3 | H10: =0.2706+(F10-17659)/194600+0.02028*$D$3+0.0*$F$3 | I10: =0.2823+(F10-17659)/194600+0.02028*$D$3+0.0*$F$3 | J10: =0.2866+(F10-17659)/137000+0.02028*$D$3+0.0*$F$3 | K10: =0.02028*$D$3+0.0*$F$3 | L10: =G10-K10 | M10: 1920 | N10: live listings ~55k mi, $15,000-$20,000 | O10: ✓ supported 2017–22 (buy ~2022 ✓) | P10: 0.364 | Q10: 2 | R10: 0.339 | S10: 0.402 | T10: 0.502 | U10: 0.159 | V10: 30962 | W10: =IFERROR(G10*INDEX('Charts data (helper)'!$BI$119:$DZ$128,MATCH($Q$3,'Charts data (helper)'!$BH$119:$BH$128,0),MATCH($B10,'Charts data (helper)'!$BI$118:$DZ$118,0))/INDEX('Charts data (helper)'!$BI$119:$DZ$128,MATCH(0.07,'Charts data (helper)'!$BH$119:$BH$128,0),MATCH($B10,'Charts data (helper)'!$BI$118:$DZ$118,0)),G10) | X10: =RANK(W10,$W$6:$W$76,1)
A11: 6 | B11: Toyota Camry Hybrid | C11: Car | D11: hybrid | E11: 80k mi → ~2020 | F11: 16500 | G11: =0.2821+(F11-16500)/169600+0.01581*$D$3+0.0*$F$3 | H11: =0.2974+(F11-16500)/169600+0.01581*$D$3+0.0*$F$3 | I11: =0.3139+(F11-16500)/169600+0.01581*$D$3+0.0*$F$3 | J11: =0.3156+(F11-16500)/112000+0.01581*$D$3+0.0*$F$3 | K11: =0.01581*$D$3+0.0*$F$3 | L11: =G11-K11 | M11: 1920 | N11: live listings ~80k mi, $14,000-$18,500 | O11: ✓ supported 2018–24 (buy ~2020 ✓) | P11: 0.367 | Q11: 2 | R11: 0.335 | S11: 0.411 | T11: 0.711 | U11: 0.138 | V11: 23387 | W11: =IFERROR(G11*INDEX('Charts data (helper)'!$BI$119:$DZ$128,MATCH($Q$3,'Charts data (helper)'!$BH$119:$BH$128,0),MATCH($B11,'Charts data (helper)'!$BI$118:$DZ$118,0))/INDEX('Charts data (helper)'!$BI$119:$DZ$128,MATCH(0.07,'Charts data (helper)'!$BH$119:$BH$128,0),MATCH($B11,'Charts data (helper)'!$BI$118:$DZ$118,0)),G11) | X11: =RANK(W11,$W$6:$W$76,1)
A12: 7 | B12: Honda Civic | C12: Car | D12: gas | E12: 35k mi → ~2023 | F12: 23789 | G12: =0.2792+(F12-23789)/200300+0.0194*$D$3+0.0*$F$3 | H12: =0.2907+(F12-23789)/200300+0.0194*$D$3+0.0*$F$3 | I12: =0.3028+(F12-23789)/200300+0.0194*$D$3+0.0*$F$3 | J12: =0.314+(F12-23789)/146000+0.0194*$D$3+0.0*$F$3 | K12: =0.0194*$D$3+0.0*$F$3 | L12: =G12-K12 | M12: 1840 | N12: live listings ~35k mi, $20,000-$27,000 | O12: ✓ supported 2016–24 (buy ~2023 ✓) | P12: 0.38 | Q12: 2 | R12: 0.357 | S12: 0.417 | T12: 0.506 | U12: 0.218 | V12: 43682 | W12: =IFERROR(G12*INDEX('Charts data (helper)'!$BI$119:$DZ$128,MATCH($Q$3,'Charts data (helper)'!$BH$119:$BH$128,0),MATCH($B12,'Charts data (helper)'!$BI$118:$DZ$118,0))/INDEX('Charts data (helper)'!$BI$119:$DZ$128,MATCH(0.07,'Charts data (helper)'!$BH$119:$BH$128,0),MATCH($B12,'Charts data (helper)'!$BI$118:$DZ$118,0)),G12) | X12: =RANK(W12,$W$6:$W$76,1)
A13: 8 | B13: Nissan Leaf | C13: EV | D13: electric | E13: 45k mi → ~2023 | F13: 11667 | G13: =0.2967+(F13-11667)/95400+0.0*$D$3+0.27831*$F$3 | H13: =0.3333+(F13-11667)/95400+0.0*$D$3+0.27831*$F$3 | I13: =0.364+(F13-11667)/95400+0.0*$D$3+0.27831*$F$3 | J13: =0.3304+(F13-11667)/63000+0.0*$D$3+0.27831*$F$3 | K13: =0.0*$D$3+0.27831*$F$3 | L13: =G13-K13 | M13: 1760 | N13: live listings ~45k mi, $9,500-$13,000 | O13: ✓ supported 2018–23 (buy ~2023 ✓) | P13: 0.419 | Q13: 2 | R13: 0.339 | S13: 0.473 | T13: 0.537 | U13: 0.079 | V13: 7501 | W13: =IFERROR(G13*INDEX('Charts data (helper)'!$BI$119:$DZ$128,MATCH($Q$3,'Charts data (helper)'!$BH$119:$BH$128,0),MATCH($B13,'Charts data (helper)'!$BI$118:$DZ$118,0))/INDEX('Charts data (helper)'!$BI$119:$DZ$128,MATCH(0.07,'Charts data (helper)'!$BH$119:$BH$128,0),MATCH($B13,'Charts data (helper)'!$BI$118:$DZ$118,0)),G13) | X13: =RANK(W13,$W$6:$W$76,1)
A14: 9 | B14: Hyundai Elantra | C14: Car | D14: gas | E14: 45k mi → ~2023 | F14: 16000 | G14: =0.2829+(F14-16000)/155200+0.0196*$D$3+0.0*$F$3 | H14: =0.2992+(F14-16000)/155200+0.0196*$D$3+0.0*$F$3 | I14: =0.3156+(F14-16000)/155200+0.0196*$D$3+0.0*$F$3 | J14: =0.3125+(F14-16000)/109000+0.0196*$D$3+0.0*$F$3 | K14: =0.0196*$D$3+0.0*$F$3 | L14: =G14-K14 | M14: 1640 | N14: live listings ~45k mi, $13,500-$18,000 | O14: ◑ Hyundai/Kia SCC, select yrs | P14: 0.385 | Q14: 2 | R14: 0.357 | S14: 0.432 | T14: 0.477 | U14: 0.128 | V14: 19885 | W14: =IFERROR(G14*INDEX('Charts data (helper)'!$BI$119:$DZ$128,MATCH($Q$3,'Charts data (helper)'!$BH$119:$BH$128,0),MATCH($B14,'Charts data (helper)'!$BI$118:$DZ$118,0))/INDEX('Charts data (helper)'!$BI$119:$DZ$128,MATCH(0.07,'Charts data (helper)'!$BH$119:$BH$128,0),MATCH($B14,'Charts data (helper)'!$BI$118:$DZ$118,0)),G14) | X14: =RANK(W14,$W$6:$W$76,1)
A15: 10 | B15: Honda Accord | C15: Car | D15: gas | E15: 70k mi → ~2021 | F15: 16143 | G15: =0.2732+(F15-16143)/170500+0.02138*$D$3+0.0*$F$3 | H15: =0.2871+(F15-16143)/170500+0.02138*$D$3+0.0*$F$3 | I15: =0.3001+(F15-16143)/170500+0.02138*$D$3+0.0*$F$3 | J15: =0.3044+(F15-16143)/115000+0.02138*$D$3+0.0*$F$3 | K15: =0.02138*$D$3+0.0*$F$3 | L15: =G15-K15 | M15: 1840 | N15: live listings ~70k mi, $13,500-$18,500 | O15: ✓ supported 2018–25 (buy ~2021 ✓) | P15: 0.386 | Q15: 2 | R15: 0.355 | S15: 0.425 | T15: 0.613 | U15: 0.135 | V15: 23064 | W15: =IFERROR(G15*INDEX('Charts data (helper)'!$BI$119:$DZ$128,MATCH($Q$3,'Charts data (helper)'!$BH$119:$BH$128,0),MATCH($B15,'Charts data (helper)'!$BI$118:$DZ$118,0))/INDEX('Charts data (helper)'!$BI$119:$DZ$128,MATCH(0.07,'Charts data (helper)'!$BH$119:$BH$128,0),MATCH($B15,'Charts data (helper)'!$BI$118:$DZ$118,0)),G15) | X15: =RANK(W15,$W$6:$W$76,1)
A16: 11 | B16: Kia K4 | C16: Car | D16: gas | E16: 18k mi → ~2025 | F16: 20125 | G16: =0.2898+(F16-20125)/171800+0.01944*$D$3+0.0*$F$3 | H16: =0.3041+(F16-20125)/171800+0.01944*$D$3+0.0*$F$3 | I16: =0.319+(F16-20125)/171800+0.01944*$D$3+0.0*$F$3 | J16: =0.3175+(F16-20125)/128000+0.01944*$D$3+0.0*$F$3 | K16: =0.01944*$D$3+0.0*$F$3 | L16: =G16-K16 | M16: 1640 | N16: live listings ~18k mi, $17,000-$23,000 | O16: ✗ too new — not yet on the comma/openpilot list | P16: 0.391 | Q16: 2 | R16: 0.369 | S16: 0.436 | T16: 0.501 | U16: 0.169 | V16: 29085 | W16: =IFERROR(G16*INDEX('Charts data (helper)'!$BI$119:$DZ$128,MATCH($Q$3,'Charts data (helper)'!$BH$119:$BH$128,0),MATCH($B16,'Charts data (helper)'!$BI$118:$DZ$118,0))/INDEX('Charts data (helper)'!$BI$119:$DZ$128,MATCH(0.07,'Charts data (helper)'!$BH$119:$BH$128,0),MATCH($B16,'Charts data (helper)'!$BI$118:$DZ$118,0)),G16) | X16: =RANK(W16,$W$6:$W$76,1)
A17: 12 | B17: Mazda3 (SkyActiv) | C17: Car | D17: gas | E17: 65k mi → ~2021 | F17: 15000 | G17: =0.2687+(F17-15000)/145600+0.02337*$D$3+0.0*$F$3 | H17: =0.2869+(F17-15000)/145600+0.02337*$D$3+0.0*$F$3 | I17: =0.3042+(F17-15000)/145600+0.02337*$D$3+0.0*$F$3 | J17: =0.3131+(F17-15000)/97000+0.02337*$D$3+0.0*$F$3 | K17: =0.02337*$D$3+0.0*$F$3 | L17: =G17-K17 | M17: 1720 | N17: live listings ~65k mi, $12,500-$17,000 | O17: ✗ not on list (only CX-5/CX-9) | P17: 0.395 | Q17: 2 | R17: 0.364 | S17: 0.441 | T17: 0.494 | U17: 0.117 | V17: 17003 | W17: =IFERROR(G17*INDEX('Charts data (helper)'!$BI$119:$DZ$128,MATCH($Q$3,'Charts data (helper)'!$BH$119:$BH$128,0),MATCH($B17,'Charts data (helper)'!$BI$118:$DZ$118,0))/INDEX('Charts data (helper)'!$BI$119:$DZ$128,MATCH(0.07,'Charts data (helper)'!$BH$119:$BH$128,0),MATCH($B17,'Charts data (helper)'!$BI$118:$DZ$118,0)),G17) | X17: =RANK(W17,$W$6:$W$76,1)
A18: 13 | B18: Toyota Camry | C18: Car | D18: gas | E18: 55k mi → ~2022 | F18: 22400 | G18: =0.284+(F18-22400)/199800+0.02072*$D$3+0.0*$F$3 | H18: =0.2974+(F18-22400)/199800+0.02072*$D$3+0.0*$F$3 | I18: =0.3114+(F18-22400)/199800+0.02072*$D$3+0.0*$F$3 | J18: =0.322+(F18-22400)/141000+0.02072*$D$3+0.0*$F$3 | K18: =0.02072*$D$3+0.0*$F$3 | L18: =G18-K18 | M18: 1840 | N18: live listings ~55k mi, $19,000-$25,500 | O18: ✓ supported 2018–24 (buy ~2022 ✓) | P18: 0.388 | Q18: 2 | R18: 0.363 | S18: 0.436 | T18: 0.514 | U18: 0.205 | V18: 40966 | W18: =IFERROR(G18*INDEX('Charts data (helper)'!$BI$119:$DZ$128,MATCH($Q$3,'Charts data (helper)'!$BH$119:$BH$128,0),MATCH($B18,'Charts data (helper)'!$BI$118:$DZ$118,0))/INDEX('Charts data (helper)'!$BI$119:$DZ$128,MATCH(0.07,'Charts data (helper)'!$BH$119:$BH$128,0),MATCH($B18,'Charts data (helper)'!$BI$118:$DZ$118,0)),G18) | X18: =RANK(W18,$W$6:$W$76,1)
A19: 14 | B19: Toyota RAV4 Hybrid | C19: SUV AWD | D19: hybrid | E19: 40k mi → ~2023 | F19: 30444 | G19: =0.3143+(F19-30444)/204400+0.01539*$D$3+0.0*$F$3 | H19: =0.3306+(F19-30444)/204400+0.01539*$D$3+0.0*$F$3 | I19: =0.3438+(F19-30444)/204400+0.01539*$D$3+0.0*$F$3 | J19: =0.3546+(F19-30444)/148000+0.01539*$D$3+0.0*$F$3 | K19: =0.01539*$D$3+0.0*$F$3 | L19: =G19-K19 | M19: 1800 | N19: live listings ~40k mi, $25,500-$35,000 | O19: ✓ supported 2016–25 (buy ~2023 ✓) | P19: 0.395 | Q19: 2 | R19: 0.359 | S19: 0.437 | T19: 0.562 | U19: 0.283 | V19: 57764 | W19: =IFERROR(G19*INDEX('Charts data (helper)'!$BI$119:$DZ$128,MATCH($Q$3,'Charts data (helper)'!$BH$119:$BH$128,0),MATCH($B19,'Charts data (helper)'!$BI$118:$DZ$118,0))/INDEX('Charts data (helper)'!$BI$119:$DZ$128,MATCH(0.07,'Charts data (helper)'!$BH$119:$BH$128,0),MATCH($B19,'Charts data (helper)'!$BI$118:$DZ$118,0)),G19) | X19: =RANK(W19,$W$6:$W$76,1)
A20: 15 | B20: Kia Niro (hybrid) | C20: SUV | D20: hybrid | E20: 65k mi → ~2021 | F20: 17000 | G20: =0.3229+(F20-17000)/140400+0.01448*$D$3+0.0*$F$3 | H20: =0.3431+(F20-17000)/140400+0.01448*$D$3+0.0*$F$3 | I20: =0.3637+(F20-17000)/140400+0.01448*$D$3+0.0*$F$3 | J20: =0.3588+(F20-17000)/93000+0.01448*$D$3+0.0*$F$3 | K20: =0.01448*$D$3+0.0*$F$3 | L20: =G20-K20 | M20: 1680 | N20: live listings ~65k mi, $14,000-$19,500 | O20: ◑ Hyundai/Kia SCC, select yrs | P20: 0.399 | Q20: 3 | R20: 0.367 | S20: 0.46 | T20: 0.594 | U20: 0.13 | V20: 18302 | W20: =IFERROR(G20*INDEX('Charts data (helper)'!$BI$119:$DZ$128,MATCH($Q$3,'Charts data (helper)'!$BH$119:$BH$128,0),MATCH($B20,'Charts data (helper)'!$BI$118:$DZ$118,0))/INDEX('Charts data (helper)'!$BI$119:$DZ$128,MATCH(0.07,'Charts data (helper)'!$BH$119:$BH$128,0),MATCH($B20,'Charts data (helper)'!$BI$118:$DZ$118,0)),G20) | X20: =RANK(W20,$W$6:$W$76,1)
A21: 16 | B21: Tesla Model 3 | C21: EV | D21: electric | E21: 60k mi → ~2021 | F21: 21500 | G21: =0.3531+(F21-21500)/170100+0.0*$D$3+0.18743*$F$3 | H21: =0.3827+(F21-21500)/170100+0.0*$D$3+0.18743*$F$3 | I21: =0.417+(F21-21500)/170100+0.0*$D$3+0.18743*$F$3 | J21: =0.3883+(F21-21500)/117000+0.0*$D$3+0.18743*$F$3 | K21: =0.0*$D$3+0.18743*$F$3 | L21: =G21-K21 | M21: 2480 | N21: live listings ~60k mi, $18,000-$24,500 | O21: ✓ supported 2019–25 (buy ~2021 ✓) | P21: 0.416 | Q21: 3 | R21: 0.367 | S21: 0.503 | T21: 0.575 | U21: 0.18 | V21: 30609 | W21: =IFERROR(G21*INDEX('Charts data (helper)'!$BI$119:$DZ$128,MATCH($Q$3,'Charts data (helper)'!$BH$119:$BH$128,0),MATCH($B21,'Charts data (helper)'!$BI$118:$DZ$118,0))/INDEX('Charts data (helper)'!$BI$119:$DZ$128,MATCH(0.07,'Charts data (helper)'!$BH$119:$BH$128,0),MATCH($B21,'Charts data (helper)'!$BI$118:$DZ$118,0)),G21) | X21: =RANK(W21,$W$6:$W$76,1)
A22: 17 | B22: Hyundai Sonata | C22: Car | D22: gas | E22: 60k mi → ~2021 | F22: 15333 | G22: =0.2998+(F22-15333)/135000+0.02244*$D$3+0.0*$F$3 | H22: =0.319+(F22-15333)/135000+0.02244*$D$3+0.0*$F$3 | I22: =0.3381+(F22-15333)/135000+0.02244*$D$3+0.0*$F$3 | J22: =0.3359+(F22-15333)/90000+0.02244*$D$3+0.0*$F$3 | K22: =0.02244*$D$3+0.0*$F$3 | L22: =G22-K22 | M22: 1720 | N22: live listings ~60k mi, $13,000-$17,500 | O22: ◑ Hyundai/Kia SCC, select yrs | P22: 0.423 | Q22: 3 | R22: 0.387 | S22: 0.478 | T22: 0.604 | U22: 0.116 | V22: 15625 | W22: =IFERROR(G22*INDEX('Charts data (helper)'!$BI$119:$DZ$128,MATCH($Q$3,'Charts data (helper)'!$BH$119:$BH$128,0),MATCH($B22,'Charts data (helper)'!$BI$118:$DZ$118,0))/INDEX('Charts data (helper)'!$BI$119:$DZ$128,MATCH(0.07,'Charts data (helper)'!$BH$119:$BH$128,0),MATCH($B22,'Charts data (helper)'!$BI$118:$DZ$118,0)),G22) | X22: =RANK(W22,$W$6:$W$76,1)
A23: 18 | B23: Toyota RAV4 | C23: SUV | D23: gas | E23: 80k mi → ~2020 | F23: 20600 | G23: =0.2992+(F23-20600)/160500+0.02421*$D$3+0.0*$F$3 | H23: =0.3152+(F23-20600)/160500+0.02421*$D$3+0.0*$F$3 | I23: =0.3318+(F23-20600)/160500+0.02421*$D$3+0.0*$F$3 | J23: =0.3362+(F23-20600)/105000+0.02421*$D$3+0.0*$F$3 | K23: =0.02421*$D$3+0.0*$F$3 | L23: =G23-K23 | M23: 1720 | N23: live listings ~80k mi, $17,500-$23,500 | O23: ✓ supported 2016–25 (buy ~2020 ✓) | P23: 0.432 | Q23: 3 | R23: 0.396 | S23: 0.477 | T23: 0.564 | U23: 0.168 | V23: 26895 | W23: =IFERROR(G23*INDEX('Charts data (helper)'!$BI$119:$DZ$128,MATCH($Q$3,'Charts data (helper)'!$BH$119:$BH$128,0),MATCH($B23,'Charts data (helper)'!$BI$118:$DZ$118,0))/INDEX('Charts data (helper)'!$BI$119:$DZ$128,MATCH(0.07,'Charts data (helper)'!$BH$119:$BH$128,0),MATCH($B23,'Charts data (helper)'!$BI$118:$DZ$118,0)),G23) | X23: =RANK(W23,$W$6:$W$76,1)
A24: 19 | B24: Fiat 500 | C24: Car | D24: gas | E24: 40k mi → ~2019 | F24: 10200 | G24: =0.3115+(F24-10200)/119900+0.02254*$D$3+0.0*$F$3 | H24: =0.3313+(F24-10200)/119900+0.02254*$D$3+0.0*$F$3 | I24: =0.3598+(F24-10200)/119900+0.02254*$D$3+0.0*$F$3 | J24: =0.3282+(F24-10200)/83000+0.02254*$D$3+0.0*$F$3 | K24: =0.02254*$D$3+0.0*$F$3 | L24: =G24-K24 | M24: 1600 | N24: live listings ~40k mi, $8,500-$11,500 | O24: ✗ not on comma list | P24: 0.435 | Q24: 3 | R24: 0.409 | S24: 0.496 | T24: 0.499 | U24: 0.074 | V24: 8837 | W24: =IFERROR(G24*INDEX('Charts data (helper)'!$BI$119:$DZ$128,MATCH($Q$3,'Charts data (helper)'!$BH$119:$BH$128,0),MATCH($B24,'Charts data (helper)'!$BI$118:$DZ$118,0))/INDEX('Charts data (helper)'!$BI$119:$DZ$128,MATCH(0.07,'Charts data (helper)'!$BH$119:$BH$128,0),MATCH($B24,'Charts data (helper)'!$BI$118:$DZ$118,0)),G24) | X24: =RANK(W24,$W$6:$W$76,1)
A25: 20 | B25: Honda CR-V | C25: SUV | D25: gas | E25: 75k mi → ~2020 | F25: 20500 | G25: =0.3069+(F25-20500)/165500+0.02394*$D$3+0.0*$F$3 | H25: =0.323+(F25-20500)/165500+0.02394*$D$3+0.0*$F$3 | I25: =0.3388+(F25-20500)/165500+0.02394*$D$3+0.0*$F$3 | J25: =0.3421+(F25-20500)/110000+0.02394*$D$3+0.0*$F$3 | K25: =0.02394*$D$3+0.0*$F$3 | L25: =G25-K25 | M25: 1680 | N25: live listings ~75k mi, $17,000-$23,500 | O25: ✓ supported 2015–26 (buy ~2020 ✓) | P25: 0.432 | Q25: 3 | R25: 0.4 | S25: 0.48 | T25: 0.514 | U25: 0.169 | V25: 28010 | W25: =IFERROR(G25*INDEX('Charts data (helper)'!$BI$119:$DZ$128,MATCH($Q$3,'Charts data (helper)'!$BH$119:$BH$128,0),MATCH($B25,'Charts data (helper)'!$BI$118:$DZ$118,0))/INDEX('Charts data (helper)'!$BI$119:$DZ$128,MATCH(0.07,'Charts data (helper)'!$BH$119:$BH$128,0),MATCH($B25,'Charts data (helper)'!$BI$118:$DZ$118,0)),G25) | X25: =RANK(W25,$W$6:$W$76,1)
A26: 21 | B26: VW ID.4 (AWD avail) | C26: EV SUV | D26: electric | E26: 45k mi → ~2023 | F26: 22500 | G26: =0.3487+(F26-22500)/150000+0.0*$D$3+0.27778*$F$3 | H26: =0.3811+(F26-22500)/150000+0.0*$D$3+0.27778*$F$3 | I26: =0.4146+(F26-22500)/150000+0.0*$D$3+0.27778*$F$3 | J26: =0.3755+(F26-22500)/105000+0.0*$D$3+0.27778*$F$3 | K26: =0.0*$D$3+0.27778*$F$3 | L26: =G26-K26 | M26: 1920 | N26: live listings ~45k mi, $19,000-$25,500 | O26: ✗ not on list (no ID.4) | P26: 0.449 | Q26: 3 | R26: 0.389 | S26: 0.529 | T26: 0.513 | U26: 0.177 | V26: 26616 | W26: =IFERROR(G26*INDEX('Charts data (helper)'!$BI$119:$DZ$128,MATCH($Q$3,'Charts data (helper)'!$BH$119:$BH$128,0),MATCH($B26,'Charts data (helper)'!$BI$118:$DZ$118,0))/INDEX('Charts data (helper)'!$BI$119:$DZ$128,MATCH(0.07,'Charts data (helper)'!$BH$119:$BH$128,0),MATCH($B26,'Charts data (helper)'!$BI$118:$DZ$118,0)),G26) | X26: =RANK(W26,$W$6:$W$76,1)
A27: 22 | B27: Toyota RAV4 Prime | C27: PHEV SUV AWD | D27: plug-in | E27: 55k mi → ~2022 | F27: 35000 | G27: =0.3549+(F27-35000)/180300+0.00427*$D$3+0.19491*$F$3 | H27: =0.3716+(F27-35000)/180300+0.00427*$D$3+0.19491*$F$3 | I27: =0.3905+(F27-35000)/180300+0.00427*$D$3+0.19491*$F$3 | J27: =0.4007+(F27-35000)/126000+0.00427*$D$3+0.19491*$F$3 | K27: =0.00427*$D$3+0.19491*$F$3 | L27: =G27-K27 | M27: 1760 | N27: live listings ~55k mi, $29,500-$40,000 | O27: ✗ not listed (RAV4 Prime absent) | P27: 0.45 | Q27: 3 | R27: 0.402 | S27: 0.484 | T27: 0.499 | U27: 0.302 | V27: 54454 | W27: =IFERROR(G27*INDEX('Charts data (helper)'!$BI$119:$DZ$128,MATCH($Q$3,'Charts data (helper)'!$BH$119:$BH$128,0),MATCH($B27,'Charts data (helper)'!$BI$118:$DZ$118,0))/INDEX('Charts data (helper)'!$BI$119:$DZ$128,MATCH(0.07,'Charts data (helper)'!$BH$119:$BH$128,0),MATCH($B27,'Charts data (helper)'!$BI$118:$DZ$118,0)),G27) | X27: =RANK(W27,$W$6:$W$76,1)
A28: 23 | B28: Kia Soul | C28: SUV | D28: gas | E28: 60k mi → ~2021 | F28: 14500 | G28: =0.3024+(F28-14500)/124600+0.02537*$D$3+0.0*$F$3 | H28: =0.3195+(F28-14500)/124600+0.02537*$D$3+0.0*$F$3 | I28: =0.34+(F28-14500)/124600+0.02537*$D$3+0.0*$F$3 | J28: =0.3387+(F28-14500)/82000+0.02537*$D$3+0.0*$F$3 | K28: =0.02537*$D$3+0.0*$F$3 | L28: =G28-K28 | M28: 1640 | N28: live listings ~60k mi, $12,000-$16,500 | O28: ◑ Hyundai/Kia SCC, select yrs | P28: 0.442 | Q28: 3 | R28: 0.406 | S28: 0.494 | T28: 0.589 | U28: 0.106 | V28: 13233 | W28: =IFERROR(G28*INDEX('Charts data (helper)'!$BI$119:$DZ$128,MATCH($Q$3,'Charts data (helper)'!$BH$119:$BH$128,0),MATCH($B28,'Charts data (helper)'!$BI$118:$DZ$118,0))/INDEX('Charts data (helper)'!$BI$119:$DZ$128,MATCH(0.07,'Charts data (helper)'!$BH$119:$BH$128,0),MATCH($B28,'Charts data (helper)'!$BI$118:$DZ$118,0)),G28) | X28: =RANK(W28,$W$6:$W$76,1)
A29: 24 | B29: VW Passat | C29: Car | D29: gas | E29: 55k mi → ~2022 | F29: 14200 | G29: =0.3068+(F29-14200)/134800+0.02566*$D$3+0.0*$F$3 | H29: =0.3276+(F29-14200)/134800+0.02566*$D$3+0.0*$F$3 | I29: =0.3485+(F29-14200)/134800+0.02566*$D$3+0.0*$F$3 | J29: =0.3397+(F29-14200)/91000+0.02566*$D$3+0.0*$F$3 | K29: =0.02566*$D$3+0.0*$F$3 | L29: =G29-K29 | M29: 1720 | N29: live listings ~55k mi, $12,000-$16,000 | O29: ◑ VW community port, select yrs | P29: 0.443 | Q29: 4 | R29: 0.412 | S29: 0.507 | T29: 0.533 | U29: 0.107 | V29: 14440 | W29: =IFERROR(G29*INDEX('Charts data (helper)'!$BI$119:$DZ$128,MATCH($Q$3,'Charts data (helper)'!$BH$119:$BH$128,0),MATCH($B29,'Charts data (helper)'!$BI$118:$DZ$118,0))/INDEX('Charts data (helper)'!$BI$119:$DZ$128,MATCH(0.07,'Charts data (helper)'!$BH$119:$BH$128,0),MATCH($B29,'Charts data (helper)'!$BI$118:$DZ$118,0)),G29) | X29: =RANK(W29,$W$6:$W$76,1)
A30: 25 | B30: Buick Encore | C30: SUV | D30: gas | E30: 50k mi → ~2022 | F30: 14800 | G30: =0.3072+(F30-14800)/125500+0.02622*$D$3+0.0*$F$3 | H30: =0.3228+(F30-14800)/125500+0.02622*$D$3+0.0*$F$3 | I30: =0.3418+(F30-14800)/125500+0.02622*$D$3+0.0*$F$3 | J30: =0.3418+(F30-14800)/85000+0.02622*$D$3+0.0*$F$3 | K30: =0.02622*$D$3+0.0*$F$3 | L30: =G30-K30 | M30: 1680 | N30: live listings ~50k mi, $12,500-$17,000 | O30: ✗ not on comma list | P30: 0.451 | Q30: 4 | R30: 0.419 | S30: 0.499 | T30: 0.559 | U30: 0.109 | V30: 13640 | W30: =IFERROR(G30*INDEX('Charts data (helper)'!$BI$119:$DZ$128,MATCH($Q$3,'Charts data (helper)'!$BH$119:$BH$128,0),MATCH($B30,'Charts data (helper)'!$BI$118:$DZ$118,0))/INDEX('Charts data (helper)'!$BI$119:$DZ$128,MATCH(0.07,'Charts data (helper)'!$BH$119:$BH$128,0),MATCH($B30,'Charts data (helper)'!$BI$118:$DZ$118,0)),G30) | X30: =RANK(W30,$W$6:$W$76,1)
A31: 26 | B31: Hyundai Kona | C31: SUV | D31: gas | E31: 65k mi → ~2021 | F31: 15000 | G31: =0.3204+(F31-15000)/119600+0.02481*$D$3+0.0*$F$3 | H31: =0.3364+(F31-15000)/119600+0.02481*$D$3+0.0*$F$3 | I31: =0.3572+(F31-15000)/119600+0.02481*$D$3+0.0*$F$3 | J31: =0.349+(F31-15000)/77000+0.02481*$D$3+0.0*$F$3 | K31: =0.02481*$D$3+0.0*$F$3 | L31: =G31-K31 | M31: 1640 | N31: live listings ~65k mi, $12,500-$17,000 | O31: ◑ Hyundai/Kia SCC, select yrs | P31: 0.459 | Q31: 4 | R31: 0.423 | S31: 0.504 | T31: 0.565 | U31: 0.108 | V31: 12953 | W31: =IFERROR(G31*INDEX('Charts data (helper)'!$BI$119:$DZ$128,MATCH($Q$3,'Charts data (helper)'!$BH$119:$BH$128,0),MATCH($B31,'Charts data (helper)'!$BI$118:$DZ$118,0))/INDEX('Charts data (helper)'!$BI$119:$DZ$128,MATCH(0.07,'Charts data (helper)'!$BH$119:$BH$128,0),MATCH($B31,'Charts data (helper)'!$BI$118:$DZ$118,0)),G31) | X31: =RANK(W31,$W$6:$W$76,1)
A32: 27 | B32: Mazda CX-5 | C32: SUV | D32: gas | E32: 65k mi → ~2021 | F32: 20600 | G32: =0.3148+(F32-20600)/149500+0.02672*$D$3+0.0*$F$3 | H32: =0.3315+(F32-20600)/149500+0.02672*$D$3+0.0*$F$3 | I32: =0.3466+(F32-20600)/149500+0.02672*$D$3+0.0*$F$3 | J32: =0.3595+(F32-20600)/100000+0.02672*$D$3+0.0*$F$3 | K32: =0.02672*$D$3+0.0*$F$3 | L32: =G32-K32 | M32: 1680 | N32: live listings ~65k mi, $17,500-$23,500 | O32: ◑ supported 2022–25 (buy ~2021 OUTSIDE range — pick a 2022-2025 example instead) | P32: 0.467 | Q32: 4 | R32: 0.427 | S32: 0.505 | T32: 0.588 | U32: 0.162 | V32: 24252 | W32: =IFERROR(G32*INDEX('Charts data (helper)'!$BI$119:$DZ$128,MATCH($Q$3,'Charts data (helper)'!$BH$119:$BH$128,0),MATCH($B32,'Charts data (helper)'!$BI$118:$DZ$118,0))/INDEX('Charts data (helper)'!$BI$119:$DZ$128,MATCH(0.07,'Charts data (helper)'!$BH$119:$BH$128,0),MATCH($B32,'Charts data (helper)'!$BI$118:$DZ$118,0)),G32) | X32: =RANK(W32,$W$6:$W$76,1)
A33: 28 | B33: Toyota Highlander Hybrid | C33: SUV AWD | D33: hybrid | E33: 65k mi → ~2021 | F33: 32000 | G33: =0.3686+(F33-32000)/179400+0.01857*$D$3+0.0*$F$3 | H33: =0.3891+(F33-32000)/179400+0.01857*$D$3+0.0*$F$3 | I33: =0.411+(F33-32000)/179400+0.01857*$D$3+0.0*$F$3 | J33: =0.4302+(F33-32000)/123000+0.01857*$D$3+0.0*$F$3 | K33: =0.01857*$D$3+0.0*$F$3 | L33: =G33-K33 | M33: 1840 | N33: live listings ~65k mi, $27,000-$36,500 | O33: ◑ select Toyota TSS years | P33: 0.463 | Q33: 4 | R33: 0.425 | S33: 0.524 | T33: 0.523 | U33: 0.275 | V33: 49404 | W33: =IFERROR(G33*INDEX('Charts data (helper)'!$BI$119:$DZ$128,MATCH($Q$3,'Charts data (helper)'!$BH$119:$BH$128,0),MATCH($B33,'Charts data (helper)'!$BI$118:$DZ$118,0))/INDEX('Charts data (helper)'!$BI$119:$DZ$128,MATCH(0.07,'Charts data (helper)'!$BH$119:$BH$128,0),MATCH($B33,'Charts data (helper)'!$BI$118:$DZ$118,0)),G33) | X33: =RANK(W33,$W$6:$W$76,1)
A34: 29 | B34: Subaru Outback | C34: SUV AWD | D34: gas | E34: 75k mi → ~2020 | F34: 18800 | G34: =0.3356+(F34-18800)/135600+0.02473*$D$3+0.0*$F$3 | H34: =0.3574+(F34-18800)/135600+0.02473*$D$3+0.0*$F$3 | I34: =0.3819+(F34-18800)/135600+0.02473*$D$3+0.0*$F$3 | J34: =0.3751+(F34-18800)/87000+0.02473*$D$3+0.0*$F$3 | K34: =0.02473*$D$3+0.0*$F$3 | L34: =G34-K34 | M34: 1640 | N34: live listings ~75k mi, $15,500-$21,500 | O34: ✓ supported 2020–22 (buy ~2020 ✓) | P34: 0.477 | Q34: 4 | R34: 0.432 | S34: 0.538 | T34: 0.504 | U34: 0.142 | V34: 19276 | W34: =IFERROR(G34*INDEX('Charts data (helper)'!$BI$119:$DZ$128,MATCH($Q$3,'Charts data (helper)'!$BH$119:$BH$128,0),MATCH($B34,'Charts data (helper)'!$BI$118:$DZ$118,0))/INDEX('Charts data (helper)'!$BI$119:$DZ$128,MATCH(0.07,'Charts data (helper)'!$BH$119:$BH$128,0),MATCH($B34,'Charts data (helper)'!$BI$118:$DZ$118,0)),G34) | X34: =RANK(W34,$W$6:$W$76,1)
A35: 30 | B35: Subaru Forester | C35: SUV AWD | D35: gas | E35: 55k mi → ~2022 | F35: 22200 | G35: =0.3394+(F35-22200)/145200+0.02419*$D$3+0.0*$F$3 | H35: =0.3564+(F35-22200)/145200+0.02419*$D$3+0.0*$F$3 | I35: =0.3761+(F35-22200)/145200+0.02419*$D$3+0.0*$F$3 | J35: =0.3746+(F35-22200)/99000+0.02419*$D$3+0.0*$F$3 | K35: =0.02419*$D$3+0.0*$F$3 | L35: =G35-K35 | M35: 1680 | N35: live listings ~55k mi, $18,500-$25,500 | O35: ◑ supported 2019–21 (buy ~2022 OUTSIDE range — pick a 2019-2021 example instead) | P35: 0.479 | Q35: 4 | R35: 0.439 | S35: 0.523 | T35: 0.486 | U35: 0.173 | V35: 25066 | W35: =IFERROR(G35*INDEX('Charts data (helper)'!$BI$119:$DZ$128,MATCH($Q$3,'Charts data (helper)'!$BH$119:$BH$128,0),MATCH($B35,'Charts data (helper)'!$BI$118:$DZ$118,0))/INDEX('Charts data (helper)'!$BI$119:$DZ$128,MATCH(0.07,'Charts data (helper)'!$BH$119:$BH$128,0),MATCH($B35,'Charts data (helper)'!$BI$118:$DZ$118,0)),G35) | X35: =RANK(W35,$W$6:$W$76,1)
A36: 31 | B36: Toyota Sienna Hybrid | C36: Van | D36: hybrid | E36: 55k mi → ~2022 | F36: 35000 | G36: =0.3765+(F36-35000)/189400+0.01766*$D$3+0.0*$F$3 | H36: =0.3984+(F36-35000)/189400+0.01766*$D$3+0.0*$F$3 | I36: =0.4175+(F36-35000)/189400+0.01766*$D$3+0.0*$F$3 | J36: =0.4354+(F36-35000)/133000+0.01766*$D$3+0.0*$F$3 | K36: =0.01766*$D$3+0.0*$F$3 | L36: =G36-K36 | M36: 1840 | N36: live listings ~55k mi, $29,500-$40,000 | O36: ◑ select Toyota TSS years | P36: 0.451 | Q36: 4 | R36: 0.416 | S36: 0.525 | T36: 0.594 | U36: 0.31 | V36: 58792 | W36: =IFERROR(G36*INDEX('Charts data (helper)'!$BI$119:$DZ$128,MATCH($Q$3,'Charts data (helper)'!$BH$119:$BH$128,0),MATCH($B36,'Charts data (helper)'!$BI$118:$DZ$118,0))/INDEX('Charts data (helper)'!$BI$119:$DZ$128,MATCH(0.07,'Charts data (helper)'!$BH$119:$BH$128,0),MATCH($B36,'Charts data (helper)'!$BI$118:$DZ$118,0)),G36) | X36: =RANK(W36,$W$6:$W$76,1)
A37: 32 | B37: Toyota Tacoma | C37: Truck | D37: gas | E37: 75k mi → ~2020 | F37: 29333 | G37: =0.3169+(F37-29333)/214900+0.03009*$D$3+0.0*$F$3 | H37: =0.3359+(F37-29333)/214900+0.03009*$D$3+0.0*$F$3 | I37: =0.3547+(F37-29333)/214900+0.03009*$D$3+0.0*$F$3 | J37: =0.3699+(F37-29333)/148000+0.03009*$D$3+0.0*$F$3 | K37: =0.03009*$D$3+0.0*$F$3 | L37: =G37-K37 | M37: 1800 | N37: live listings ~75k mi, $24,500-$33,500 | O37: ✗ not supported (no Tacoma on list) | P37: 0.474 | Q37: 4 | R37: 0.44 | S37: 0.531 | T37: 0.57 | U37: 0.281 | V37: 60430 | W37: =IFERROR(G37*INDEX('Charts data (helper)'!$BI$119:$DZ$128,MATCH($Q$3,'Charts data (helper)'!$BH$119:$BH$128,0),MATCH($B37,'Charts data (helper)'!$BI$118:$DZ$118,0))/INDEX('Charts data (helper)'!$BI$119:$DZ$128,MATCH(0.07,'Charts data (helper)'!$BH$119:$BH$128,0),MATCH($B37,'Charts data (helper)'!$BI$118:$DZ$118,0)),G37) | X37: =RANK(W37,$W$6:$W$76,1)
A38: 33 | B38: Nissan Rogue | C38: SUV | D38: gas | E38: 55k mi → ~2022 | F38: 18800 | G38: =0.3443+(F38-18800)/115300+0.02592*$D$3+0.0*$F$3 | H38: =0.3648+(F38-18800)/115300+0.02592*$D$3+0.0*$F$3 | I38: =0.3873+(F38-18800)/115300+0.02592*$D$3+0.0*$F$3 | J38: =0.3805+(F38-18800)/76000+0.02592*$D$3+0.0*$F$3 | K38: =0.02592*$D$3+0.0*$F$3 | L38: =G38-K38 | M38: 1664 | N38: live listings ~55k mi, $15,500-$21,500 | O38: ◑ supported 2018–20 (buy ~2022 OUTSIDE range — pick a 2018-2020 example instead) | P38: 0.498 | Q38: 4 | R38: 0.451 | S38: 0.541 | T38: 0.527 | U38: 0.134 | V38: 15459 | W38: =IFERROR(G38*INDEX('Charts data (helper)'!$BI$119:$DZ$128,MATCH($Q$3,'Charts data (helper)'!$BH$119:$BH$128,0),MATCH($B38,'Charts data (helper)'!$BI$118:$DZ$118,0))/INDEX('Charts data (helper)'!$BI$119:$DZ$128,MATCH(0.07,'Charts data (helper)'!$BH$119:$BH$128,0),MATCH($B38,'Charts data (helper)'!$BI$118:$DZ$118,0)),G38) | X38: =RANK(W38,$W$6:$W$76,1)
A39: 34 | B39: Chevy Equinox | C39: SUV | D39: gas | E39: 55k mi → ~2022 | F39: 17200 | G39: =0.3379+(F39-17200)/120500+0.02751*$D$3+0.0*$F$3 | H39: =0.3571+(F39-17200)/120500+0.02751*$D$3+0.0*$F$3 | I39: =0.3808+(F39-17200)/120500+0.02751*$D$3+0.0*$F$3 | J39: =0.3628+(F39-17200)/80000+0.02751*$D$3+0.0*$F$3 | K39: =0.02751*$D$3+0.0*$F$3 | L39: =G39-K39 | M39: 1720 | N39: live listings ~55k mi, $14,500-$19,500 | O39: ✓ supported 2019–22 (buy ~2022 ✓) | P39: 0.498 | Q39: 5 | R39: 0.455 | S39: 0.546 | T39: 0.534 | U39: 0.125 | V39: 15003 | W39: =IFERROR(G39*INDEX('Charts data (helper)'!$BI$119:$DZ$128,MATCH($Q$3,'Charts data (helper)'!$BH$119:$BH$128,0),MATCH($B39,'Charts data (helper)'!$BI$118:$DZ$118,0))/INDEX('Charts data (helper)'!$BI$119:$DZ$128,MATCH(0.07,'Charts data (helper)'!$BH$119:$BH$128,0),MATCH($B39,'Charts data (helper)'!$BI$118:$DZ$118,0)),G39) | X39: =RANK(W39,$W$6:$W$76,1)
A40: 35 | B40: Toyota Sienna (V6) | C40: Van | D40: gas | E40: 65k mi → ~2020 | F40: 22333 | G40: =0.3065+(F40-22333)/179400+0.0342*$D$3+0.0*$F$3 | H40: =0.3217+(F40-22333)/179400+0.0342*$D$3+0.0*$F$3 | I40: =0.336+(F40-22333)/179400+0.0342*$D$3+0.0*$F$3 | J40: =0.3502+(F40-22333)/123000+0.0342*$D$3+0.0*$F$3 | K40: =0.0342*$D$3+0.0*$F$3 | L40: =G40-K40 | M40: 1720 | N40: live listings ~65k mi, $18,500-$25,500 | O40: ✗ not on list | P40: 0.483 | Q40: 5 | R40: 0.457 | S40: 0.533 | T40: 0.519 | U40: 0.192 | V40: 34480 | W40: =IFERROR(G40*INDEX('Charts data (helper)'!$BI$119:$DZ$128,MATCH($Q$3,'Charts data (helper)'!$BH$119:$BH$128,0),MATCH($B40,'Charts data (helper)'!$BI$118:$DZ$118,0))/INDEX('Charts data (helper)'!$BI$119:$DZ$128,MATCH(0.07,'Charts data (helper)'!$BH$119:$BH$128,0),MATCH($B40,'Charts data (helper)'!$BI$118:$DZ$118,0)),G40) | X40: =RANK(W40,$W$6:$W$76,1)
A41: 36 | B41: Mini Cooper | C41: Car | D41: gas | E41: 45k mi → ~2023 | F41: 18200 | G41: =0.3615+(F41-18200)/130500+0.02419*$D$3+0.0*$F$3 | H41: =0.3847+(F41-18200)/130500+0.02419*$D$3+0.0*$F$3 | I41: =0.413+(F41-18200)/130500+0.02419*$D$3+0.0*$F$3 | J41: =0.3922+(F41-18200)/90000+0.02419*$D$3+0.0*$F$3 | K41: =0.02419*$D$3+0.0*$F$3 | L41: =G41-K41 | M41: 1720 | N41: live listings ~45k mi, $15,000-$20,500 | O41: ✗ not on comma list | P41: 0.488 | Q41: 5 | R41: 0.451 | S41: 0.566 | T41: 0.528 | U41: 0.136 | V41: 17695 | W41: =IFERROR(G41*INDEX('Charts data (helper)'!$BI$119:$DZ$128,MATCH($Q$3,'Charts data (helper)'!$BH$119:$BH$128,0),MATCH($B41,'Charts data (helper)'!$BI$118:$DZ$118,0))/INDEX('Charts data (helper)'!$BI$119:$DZ$128,MATCH(0.07,'Charts data (helper)'!$BH$119:$BH$128,0),MATCH($B41,'Charts data (helper)'!$BI$118:$DZ$118,0)),G41) | X41: =RANK(W41,$W$6:$W$76,1)
